Workbook

Sheet Summary
A1: FW26 OTB - Summary (EUR k)
A3: Regione | B3: Planned Sales | C3: Actual Sales (Aug-Oct MTD) | D3: Plan Aug-Oct | E3: Var % | F3: Planned Receipts | G3: On Order | H3: OTB residuo
A4: EMEA | B4: =EMEA!I53 -> 139300 | C4: =EMEA!I54 -> 33674 | D4: =SUM(EMEA!C53:E53) -> 42113 | E4: =C4/D4-1 -> -0.20038943 | F4: =EMEA!I58 -> 165966 | G4: =EMEA!I59 -> 130721 | H4: =EMEA!I60 -> 35245
A5: AMERICAS | B5: =AMERICAS!I53 -> 37168 | C5: =AMERICAS!I54 -> 8975 | D5: =SUM(AMERICAS!C53:E53) -> 11003 | E5: =C5/D5-1 -> -0.18431337 | F5: =AMERICAS!I58 -> 44004 | G5: =AMERICAS!I59 -> 35292 | H5: =AMERICAS!I60 -> 8712
A6: APAC | B6: =APAC!I53 -> 136543 | C6: =APAC!I54 -> 39838 | D6: =SUM(APAC!C53:E53) -> 45022 | E6: =C6/D6-1 -> -0.11514371 | F6: =APAC!I58 -> 155626 | G6: =APAC!I59 -> 125714 | H6: =APAC!I60 -> 29912
A7: TOTALE | B7: =SUM(B4:B6) -> 313011 | C7: =SUM(C4:C6) -> 82487 | D7: =SUM(D4:D6) -> 98138 | E7: =C7/D7-1 -> -0.15947951 | F7: =SUM(F4:F6) -> 365596 | G7: =SUM(G4:G6) -> 291727 | H7: =SUM(H4:H6) -> 73869
A9: NB: Oct actual = MTD 21/10 vs full-month plan -> var% Oct non confrontabile

Sheet Assumptions
A1: FW26 Merchandise Plan / OTB - Assunzioni
A2: Valori in EUR k al cambio budget 2026, retail value. Versione v5 - 14/09/2026 (G. Bellini)
A4: Regione | B4: Crescita vs LY | C4: Note
A5: EMEA | B5: 1.05 | C5: incl. Golden Week Milano/Parigi
A6: AMERICAS | B6: 1.04 | C6: campagna FW26 US/UK da 15/9 (+ agenzia stima +20%?)
A7: APAC | B7: 1.09 | C7: Couture Astra + Cina forte
A9: Categoria | B9: Adj. crescita | C9: Mesi copertura EOP (WOC/4)
A10: Outerwear | B10: 1.03 | C10: 2.4
A11: Knitwear | B11: 1.02 | C11: 2
A12: Jersey | B12: 0.98 | C12: 1.6
A13: Footwear | B13: 1 | C13: 2.2
A14: Accessories | B14: 1.04 | C14: 1.8
A15: Bottoms | B15: 1 | C15: 2.5
A17: Astra (Couture) | B17: Piano EU = profilo Couture drop 2025 (CN/HK), fattore 1.0 | C17: da rivedere dopo lancio 24/9
A18: IRIDIA | B18: analogo ARIA x 0,55 (allocazione) / forecast stat. ARIA x 0,6 | C18: colore 510 rosa cipria = 20% buy
A19: SYD01 | B19: profilo stagionalità NH_STD (come EMEA) | C19: ?? chiedere a Daniel Lim

Sheet EMEA
A1: OTB FW26 - EMEA
A2: EUR k - retail @ budget FX
C3: Q3 FY26 | E3: Q4 FY26 | H3: Q1 FY27 | I3: Season
A4: Categoria | B4: Misura | C4: Ago-26 | D4: Set-26 | E4: Ott-26 | F4: Nov-26 | G4: Dic-26 | H4: Gen-27 | I4: TOT
A5: Outerwear | B5: Planned Sales | C5: 5560 | D5: 8965 | E5: 14876 | F5: 20333 | G5: 33115 | H5: 21603 | I5: =SUM(C5:H5) -> 104452
B6: Actual Sales | C6: 4617 | D6: 8508 | E6: 9627 | I6: =SUM(C6:H6) -> 22752
B7: Var % vs plan | C7: =IF(C6="","",C6/C5-1) -> -0.16960432 | D7: =IF(D6="","",D6/D5-1) -> -0.050976018 | E7: =IF(E6="","",E6/E5-1) -> -0.35285023 | F7: =IF(F6="","",F6/F5-1) | G7: =IF(G6="","",G6/G5-1) | H7: =IF(H6="","",H6/H5-1) | I7: =IF(SUM(C6:E6)=0,"",SUM(C6:E6)/SUM(C5:E5)-1) -> -0.22614877
B8: BOP | C8: 11364 | D8: =C9 -> 21516 | E8: =D9 -> 35702 | F8: =E9 -> 48799 | G8: =F9 -> 79476 | H8: =G9 -> 51847 | I8: =C8 -> 11364
B9: Planned EOP | C9: 21516 | D9: 35702 | E9: 48799 | F9: 79476 | G9: 51847 | H9: 36293 | I9: =H9 -> 36293
B10: Planned Receipts | C10: =C5+C9-C8 -> 15712 | D10: =D5+D9-D8 -> 23151 | E10: =E5+E9-E8 -> 27973 | F10: =F5+F9-F8 -> 51010 | G10: =G5+G9-G8 -> 5486 | H10: =H5+H9-H8 -> 6049 | I10: =SUM(C10:H10) -> 129381
B11: On Order | C11: 16423 | D11: 22926 | E11: 25425 | F11: 34034 | G11: 2472 | H11: 1181 | I11: =SUM(C11:H11) -> 102461
B12: OTB | C12: =C10-C11 -> -711 | D12: =D10-D11 -> 225 | E12: =E10-E11 -> 2548 | F12: =F10-F11 -> 16976 | G12: =G10-G11 -> 3014 | H12: =H10-H11 -> 4868 | I12: =SUM(C12:H12) -> 26920
A13: Knitwear | B13: Planned Sales | C13: 1255 | D13: 1478 | E13: 1724 | F13: 2108 | G13: 3222 | H13: 2097 | I13: =SUM(C13:H13) -> 11884
B14: Actual Sales | C14: 1084 | D14: 1575 | E14: 1302 | I14: =SUM(C14:H14) -> 3961
B15: Var % vs plan | C15: =IF(C14="","",C14/C13-1) -> -0.13625498 | D15: =IF(D14="","",D14/D13-1) -> 0.065629229 | E15: =IF(E14="","",E14/E13-1) -> -0.24477958 | F15: =IF(F14="","",F14/F13-1) | G15: =IF(G14="","",G14/G13-1) | H15: =IF(H14="","",H14/H13-1) | I15: =IF(SUM(C14:E14)=0,"",SUM(C14:E14)/SUM(C13:E13)-1) -> -0.11128562
B16: BOP | C16: 2585 | D16: =C17 -> 2956 | E16: =D17 -> 3448 | F16: =E17 -> 4216 | G16: =F17 -> 6444 | H16: =G17 -> 4194 | I16: =C16 -> 2585
B17: Planned EOP | C17: 2956 | D17: 3448 | E17: 4216 | F17: 6444 | G17: 4194 | H17: 2936 | I17: =H17 -> 2936
B18: Planned Receipts | C18: =C13+C17-C16 -> 1626 | D18: =D13+D17-D16 -> 1970 | E18: =E13+E17-E16 -> 2492 | F18: =F13+F17-F16 -> 4336 | G18: =G13+G17-G16 -> 972 | H18: =H13+H17-H16 -> 839 | I18: =SUM(C18:H18) -> 12235
B19: On Order | C19: 1684 | D19: 2013 | E19: 2351 | F19: 3008 | G19: 422 | H19: 175 | I19: =SUM(C19:H19) -> 9653
B20: OTB | C20: =C18-C19 -> -58 | D20: =D18-D19 -> -43 | E20: =E18-E19 -> 141 | F20: =F18-F19 -> 1328 | G20: =G18-G19 -> 550 | H20: =H18-H19 -> 664 | I20: =SUM(C20:H20) -> 2582
A21: Jersey | B21: Planned Sales | C21: 1190 | D21: 1110 | E21: 1135 | F21: 1220 | G21: 1789 | H21: 1257 | I21: =SUM(C21:H21) -> 7701
B22: Actual Sales | C22: 1124 | D22: 1013 | E22: 770 | I22: =SUM(C22:H22) -> 2907
B23: Var % vs plan | C23: =IF(C22="","",C22/C21-1) -> -0.055462185 | D23: =IF(D22="","",D22/D21-1) -> -0.087387387 | E23: =IF(E22="","",E22/E21-1) -> -0.3215859 | F23: =IF(F22="","",F22/F21-1) | G23: =IF(G22="","",G22/G21-1) | H23: =IF(H22="","",H22/H21-1) | I23: =IF(SUM(C22:E22)=0,"",SUM(C22:E22)/SUM(C21:E21)-1) -> -0.15371179
B24: BOP | C24: 1912 | D24: =C25 -> 1776 | E24: =D25 -> 1816 | F24: =E25 -> 1952 | G24: =F25 -> 2862 | H24: =G25 -> 2011 | I24: =C24 -> 1912
B25: Planned EOP | C25: 1776 | D25: 1816 | E25: 1952 | F25: 2862 | G25: 2011 | H25: 1408 | I25: =H25 -> 1408
B26: Planned Receipts | C26: =C21+C25-C24 -> 1054 | D26: =D21+D25-D24 -> 1150 | E26: =E21+E25-E24 -> 1271 | F26: =F21+F25-F24 -> 2130 | G26: =G21+G25-G24 -> 938 | H26: =H21+H25-H24 -> 654 | I26: =SUM(C26:H26) -> 7197
B27: On Order | C27: 1026 | D27: 1188 | E27: 1179 | F27: 1441 | G27: 411 | H27: 132 | I27: =SUM(C27:H27) -> 5377
B28: OTB | C28: =C26-C27 -> 28 | D28: =D26-D27 -> -38 | E28: =E26-E27 -> 92 | F28: =F26-F27 -> 689 | G28: =G26-G27 -> 527 | H28: =H26-H27 -> 522 | I28: =SUM(C28:H28) -> 1820
A29: Footwear | B29: Planned Sales | C29: 514 | D29: 688 | E29: 836 | F29: 1119 | G29: 1944 | H29: 1258 | I29: =SUM(C29:H29) -> 6359
B30: Actual Sales | C30: 495 | D30: 644 | E30: 601 | I30: =SUM(C30:H30) -> 1740
B31: Var % vs plan | C31: =IF(C30="","",C30/C29-1) -> -0.036964981 | D31: =IF(D30="","",D30/D29-1) -> -0.063953488 | E31: =IF(E30="","",E30/E29-1) -> -0.28110048 | F31: =IF(F30="","",F30/F29-1) | G31: =IF(G30="","",G30/G29-1) | H31: =IF(H30="","",H30/H29-1) | I31: =IF(SUM(C30:E30)=0,"",SUM(C30:E30)/SUM(C29:E29)-1) -> -0.14622179
B32: BOP | C32: 1100 | D32: =C33 -> 1514 | E32: =D33 -> 1839 | F32: =E33 -> 2462 | G32: =F33 -> 4277 | H32: =G33 -> 2768 | I32: =C32 -> 1100
B33: Planned EOP | C33: 1514 | D33: 1839 | E33: 2462 | F33: 4277 | G33: 2768 | H33: 1938 | I33: =H33 -> 1938
B34: Planned Receipts | C34: =C29+C33-C32 -> 928 | D34: =D29+D33-D32 -> 1013 | E34: =E29+E33-E32 -> 1459 | F34: =F29+F33-F32 -> 2934 | G34: =G29+G33-G32 -> 435 | H34: =H29+H33-H32 -> 428 | I34: =SUM(C34:H34) -> 7197
B35: On Order | C35: 933 | D35: 1043 | E35: 1363 | F35: 2049 | G35: 196 | H35: 90 | I35: =SUM(C35:H35) -> 5674
B36: OTB | C36: =C34-C35 -> -5 | D36: =D34-D35 -> -30 | E36: =E34-E35 -> 96 | F36: =F34-F35 -> 885 | G36: =G34-G35 -> 239 | H36: =H34-H35 -> 338 | I36: =SUM(C36:H36) -> 1523
A37: Accessories | B37: Planned Sales | C37: 652 | D37: 784 | E37: 1048 | F37: 1346 | G37: 2236 | H37: 1480 | I37: =SUM(C37:H37) -> 7546
B38: Actual Sales | C38: 582 | D38: 724 | E38: 795 | I38: =SUM(C38:H38) -> 2101
B39: Var % vs plan | C39: =IF(C38="","",C38/C37-1) -> -0.10736196 | D39: =IF(D38="","",D38/D37-1) -> -0.076530612 | E39: =IF(E38="","",E38/E37-1) -> -0.24141221 | F39: =IF(F38="","",F38/F37-1) | G39: =IF(G38="","",G38/G37-1) | H39: =IF(H38="","",H38/H37-1) | I39: =IF(SUM(C38:E38)=0,"",SUM(C38:E38)/SUM(C37:E37)-1) -> -0.1541868
B40: BOP | C40: 1197 | D40: =C41 -> 1411 | E40: =D41 -> 1886 | F40: =E41 -> 2423 | G40: =F41 -> 4025 | H40: =G41 -> 2664 | I40: =C40 -> 1197
...

Sheet AMERICAS
A1: OTB FW26 - AMERICAS
A2: EUR k - retail @ budget FX
C3: Q3 FY26 | E3: Q4 FY26 | H3: Q1 FY27 | I3: Season
A4: Categoria | B4: Misura | C4: Ago-26 | D4: Set-26 | E4: Ott-26 | F4: Nov-26 | G4: Dic-26 | H4: Gen-27 | I4: TOT
A5: Outerwear | B5: Planned Sales | C5: 1524 | D5: 2374 | E5: 3781 | F5: 5805 | G5: 8656 | H5: 5855 | I5: =SUM(C5:H5) -> 27995
B6: Actual Sales | C6: 1352 | D6: 2330 | E6: 2421 | I6: =SUM(C6:H6) -> 6103
B7: Var % vs plan | C7: =IF(C6="","",C6/C5-1) -> -0.11286089 | D7: =IF(D6="","",D6/D5-1) -> -0.01853412 | E7: =IF(E6="","",E6/E5-1) -> -0.3596932 | F7: =IF(F6="","",F6/F5-1) | G7: =IF(G6="","",G6/G5-1) | H7: =IF(H6="","",H6/H5-1) | I7: =IF(SUM(C6:E6)=0,"",SUM(C6:E6)/SUM(C5:E5)-1) -> -0.20523506
B8: BOP | C8: 3565 | D8: =C9 -> 5698 | E8: =D9 -> 9074 | F8: =E9 -> 13932 | G8: =F9 -> 20774 | H8: =G9 -> 14052 | I8: =C8 -> 3565
B9: Planned EOP | C9: 5698 | D9: 9074 | E9: 13932 | F9: 20774 | G9: 14052 | H9: 9835 | I9: =H9 -> 9835
B10: Planned Receipts | C10: =C5+C9-C8 -> 3657 | D10: =D5+D9-D8 -> 5750 | E10: =E5+E9-E8 -> 8639 | F10: =F5+F9-F8 -> 12647 | G10: =G5+G9-G8 -> 1934 | H10: =H5+H9-H8 -> 1638 | I10: =SUM(C10:H10) -> 34265
B11: On Order | C11: 3628 | D11: 5675 | E11: 8336 | F11: 9000 | G11: 853 | H11: 315 | I11: =SUM(C11:H11) -> 27807
B12: OTB | C12: =C10-C11 -> 29 | D12: =D10-D11 -> 75 | E12: =E10-E11 -> 303 | F12: =F10-F11 -> 3647 | G12: =G10-G11 -> 1081 | H12: =H10-H11 -> 1323 | I12: =SUM(C12:H12) -> 6458
A13: Knitwear | B13: Planned Sales | C13: 282 | D13: 372 | E13: 409 | F13: 497 | G13: 818 | H13: 576 | I13: =SUM(C13:H13) -> 2954
B14: Actual Sales | C14: 280 | D14: 358 | E14: 304 | I14: =SUM(C14:H14) -> 942
B15: Var % vs plan | C15: =IF(C14="","",C14/C13-1) -> -0.0070921986 | D15: =IF(D14="","",D14/D13-1) -> -0.037634409 | E15: =IF(E14="","",E14/E13-1) -> -0.25672372 | F15: =IF(F14="","",F14/F13-1) | G15: =IF(G14="","",G14/G13-1) | H15: =IF(H14="","",H14/H13-1) | I15: =IF(SUM(C14:E14)=0,"",SUM(C14:E14)/SUM(C13:E13)-1) -> -0.11382879
B16: BOP | C16: 574 | D16: =C17 -> 744 | E16: =D17 -> 818 | F16: =E17 -> 994 | G16: =F17 -> 1636 | H16: =G17 -> 1152 | I16: =C16 -> 574
B17: Planned EOP | C17: 744 | D17: 818 | E17: 994 | F17: 1636 | G17: 1152 | H17: 806 | I17: =H17 -> 806
B18: Planned Receipts | C18: =C13+C17-C16 -> 452 | D18: =D13+D17-D16 -> 446 | E18: =E13+E17-E16 -> 585 | F18: =F13+F17-F16 -> 1139 | G18: =G13+G17-G16 -> 334 | H18: =H13+H17-H16 -> 230 | I18: =SUM(C18:H18) -> 3186
B19: On Order | C19: 466 | D19: 441 | E19: 511 | F19: 801 | G19: 146 | H19: 44 | I19: =SUM(C19:H19) -> 2409
B20: OTB | C20: =C18-C19 -> -14 | D20: =D18-D19 -> 5 | E20: =E18-E19 -> 74 | F20: =F18-F19 -> 338 | G20: =G18-G19 -> 188 | H20: =H18-H19 -> 186 | I20: =SUM(C20:H20) -> 777
A21: Jersey | B21: Planned Sales | C21: 357 | D21: 341 | E21: 344 | F21: 392 | G21: 518 | H21: 400 | I21: =SUM(C21:H21) -> 2352
B22: Actual Sales | C22: 366 | D22: 324 | E22: 250 | I22: =SUM(C22:H22) -> 940
B23: Var % vs plan | C23: =IF(C22="","",C22/C21-1) -> 0.025210084 | D23: =IF(D22="","",D22/D21-1) -> -0.049853372 | E23: =IF(E22="","",E22/E21-1) -> -0.27325581 | F23: =IF(F22="","",F22/F21-1) | G23: =IF(G22="","",G22/G21-1) | H23: =IF(H22="","",H22/H21-1) | I23: =IF(SUM(C22:E22)=0,"",SUM(C22:E22)/SUM(C21:E21)-1) -> -0.097888676
B24: BOP | C24: 599 | D24: =C25 -> 546 | E24: =D25 -> 550 | F24: =E25 -> 627 | G24: =F25 -> 829 | H24: =G25 -> 640 | I24: =C24 -> 599
B25: Planned EOP | C25: 546 | D25: 550 | E25: 627 | F25: 829 | G25: 640 | H25: 448 | I25: =H25 -> 448
B26: Planned Receipts | C26: =C21+C25-C24 -> 304 | D26: =D21+D25-D24 -> 345 | E26: =E21+E25-E24 -> 421 | F26: =F21+F25-F24 -> 594 | G26: =G21+G25-G24 -> 329 | H26: =H21+H25-H24 -> 208 | I26: =SUM(C26:H26) -> 2201
B27: On Order | C27: 317 | D27: 355 | E27: 392 | F27: 410 | G27: 142 | H27: 42 | I27: =SUM(C27:H27) -> 1658
B28: OTB | C28: =C26-C27 -> -13 | D28: =D26-D27 -> -10 | E28: =E26-E27 -> 29 | F28: =F26-F27 -> 184 | G28: =G26-G27 -> 187 | H28: =H26-H27 -> 166 | I28: =SUM(C28:H28) -> 543
A29: Footwear | B29: Planned Sales | C29: 145 | D29: 173 | E29: 219 | F29: 270 | G29: 472 | H29: 331 | I29: =SUM(C29:H29) -> 1610
B30: Actual Sales | C30: 112 | D30: 159 | E30: 161 | I30: =SUM(C30:H30) -> 432
B31: Var % vs plan | C31: =IF(C30="","",C30/C29-1) -> -0.22758621 | D31: =IF(D30="","",D30/D29-1) -> -0.080924855 | E31: =IF(E30="","",E30/E29-1) -> -0.26484018 | F31: =IF(F30="","",F30/F29-1) | G31: =IF(G30="","",G30/G29-1) | H31: =IF(H30="","",H30/H29-1) | I31: =IF(SUM(C30:E30)=0,"",SUM(C30:E30)/SUM(C29:E29)-1) -> -0.19553073
B32: BOP | C32: 287 | D32: =C33 -> 381 | E32: =D33 -> 482 | F32: =E33 -> 594 | G32: =F33 -> 1038 | H32: =G33 -> 728 | I32: =C32 -> 287
B33: Planned EOP | C33: 381 | D33: 482 | E33: 594 | F33: 1038 | G33: 728 | H33: 510 | I33: =H33 -> 510
B34: Planned Receipts | C34: =C29+C33-C32 -> 239 | D34: =D29+D33-D32 -> 274 | E34: =E29+E33-E32 -> 331 | F34: =F29+F33-F32 -> 714 | G34: =G29+G33-G32 -> 162 | H34: =H29+H33-H32 -> 113 | I34: =SUM(C34:H34) -> 1833
B35: On Order | C35: 248 | D35: 263 | E35: 301 | F35: 509 | G35: 76 | H35: 23 | I35: =SUM(C35:H35) -> 1420
B36: OTB | C36: =C34-C35 -> -9 | D36: =D34-D35 -> 11 | E36: =E34-E35 -> 30 | F36: =F34-F35 -> 205 | G36: =G34-G35 -> 86 | H36: =H34-H35 -> 90 | I36: =SUM(C36:H36) -> 413
A37: Accessories | B37: Planned Sales | C37: 163 | D37: 213 | E37: 245 | F37: 355 | G37: 609 | H37: 372 | I37: =SUM(C37:H37) -> 1957
B38: Actual Sales | C38: 156 | D38: 173 | E38: 188 | I38: =SUM(C38:H38) -> 517
B39: Var % vs plan | C39: =IF(C38="","",C38/C37-1) -> -0.042944785 | D39: =IF(D38="","",D38/D37-1) -> -0.18779343 | E39: =IF(E38="","",E38/E37-1) -> -0.23265306 | F39: =IF(F38="","",F38/F37-1) | G39: =IF(G38="","",G38/G37-1) | H39: =IF(H38="","",H38/H37-1) | I39: =IF(SUM(C38:E38)=0,"",SUM(C38:E38)/SUM(C37:E37)-1) -> -0.16747182
B40: BOP | C40: 279 | D40: =C41 -> 383 | E40: =D41 -> 441 | F40: =E41 -> 639 | G40: =F41 -> 1096 | H40: =G41 -> 670 | I40: =C40 -> 279
...

Sheet APAC
A1: OTB FW26 - APAC
A2: EUR k - retail @ budget FX
C3: Q3 FY26 | E3: Q4 FY26 | H3: Q1 FY27 | I3: Season
A4: Categoria | B4: Misura | C4: Ago-26 | D4: Set-26 | E4: Ott-26 | F4: Nov-26 | G4: Dic-26 | H4: Gen-27 | I4: TOT
A5: Outerwear | B5: Planned Sales | C5: 6159 | D5: 9956 | E5: 14883 | F5: 21427 | G5: 29985 | H5: 19931 | I5: =SUM(C5:H5) -> 102341
B6: Actual Sales | C6: 5498 | D6: 10160 | E6: 11674 | I6: =SUM(C6:H6) -> 27332
B7: Var % vs plan | C7: =IF(C6="","",C6/C5-1) -> -0.10732262 | D7: =IF(D6="","",D6/D5-1) -> 0.020490157 | E7: =IF(E6="","",E6/E5-1) -> -0.21561513 | F7: =IF(F6="","",F6/F5-1) | G7: =IF(G6="","",G6/G5-1) | H7: =IF(H6="","",H6/H5-1) | I7: =IF(SUM(C6:E6)=0,"",SUM(C6:E6)/SUM(C5:E5)-1) -> -0.11826569
B8: BOP | C8: 14974 | D8: =C9 -> 23894 | E8: =D9 -> 35719 | F8: =E9 -> 51425 | G8: =F9 -> 71964 | H8: =G9 -> 47834 | I8: =C8 -> 14974
B9: Planned EOP | C9: 23894 | D9: 35719 | E9: 51425 | F9: 71964 | G9: 47834 | H9: 33485 | I9: =H9 -> 33485
B10: Planned Receipts | C10: =C5+C9-C8 -> 15079 | D10: =D5+D9-D8 -> 21781 | E10: =E5+E9-E8 -> 30589 | F10: =F5+F9-F8 -> 41966 | G10: =G5+G9-G8 -> 5855 | H10: =H5+H9-H8 -> 5582 | I10: =SUM(C10:H10) -> 120852
B11: On Order | C11: 14641 | D11: 20811 | E11: 29467 | F11: 30135 | G11: 2667 | H11: 1109 | I11: =SUM(C11:H11) -> 98830
B12: OTB | C12: =C10-C11 -> 438 | D12: =D10-D11 -> 970 | E12: =E10-E11 -> 1122 | F12: =F10-F11 -> 11831 | G12: =G10-G11 -> 3188 | H12: =H10-H11 -> 4473 | I12: =SUM(C12:H12) -> 22022
A13: Knitwear | B13: Planned Sales | C13: 1480 | D13: 1610 | E13: 1949 | F13: 2085 | G13: 2814 | H13: 2138 | I13: =SUM(C13:H13) -> 12076
B14: Actual Sales | C14: 1340 | D14: 1768 | E14: 1689 | I14: =SUM(C14:H14) -> 4797
B15: Var % vs plan | C15: =IF(C14="","",C14/C13-1) -> -0.094594595 | D15: =IF(D14="","",D14/D13-1) -> 0.098136646 | E15: =IF(E14="","",E14/E13-1) -> -0.13340174 | F15: =IF(F14="","",F14/F13-1) | G15: =IF(G14="","",G14/G13-1) | H15: =IF(H14="","",H14/H13-1) | I15: =IF(SUM(C14:E14)=0,"",SUM(C14:E14)/SUM(C13:E13)-1) -> -0.048025402
B16: BOP | C16: 2696 | D16: =C17 -> 3220 | E16: =D17 -> 3898 | F16: =E17 -> 4170 | G16: =F17 -> 5628 | H16: =G17 -> 4276 | I16: =C16 -> 2696
B17: Planned EOP | C17: 3220 | D17: 3898 | E17: 4170 | F17: 5628 | G17: 4276 | H17: 2994 | I17: =H17 -> 2994
B18: Planned Receipts | C18: =C13+C17-C16 -> 2004 | D18: =D13+D17-D16 -> 2288 | E18: =E13+E17-E16 -> 2221 | F18: =F13+F17-F16 -> 3543 | G18: =G13+G17-G16 -> 1462 | H18: =H13+H17-H16 -> 856 | I18: =SUM(C18:H18) -> 12374
B19: On Order | C19: 1909 | D19: 2209 | E19: 1975 | F19: 2510 | G19: 629 | H19: 169 | I19: =SUM(C19:H19) -> 9401
B20: OTB | C20: =C18-C19 -> 95 | D20: =D18-D19 -> 79 | E20: =E18-E19 -> 246 | F20: =F18-F19 -> 1033 | G20: =G18-G19 -> 833 | H20: =H18-H19 -> 687 | I20: =SUM(C20:H20) -> 2973
A21: Jersey | B21: Planned Sales | C21: 1298 | D21: 1202 | E21: 1339 | F21: 1294 | G21: 1894 | H21: 1361 | I21: =SUM(C21:H21) -> 8388
B22: Actual Sales | C22: 1304 | D22: 1229 | E22: 937 | I22: =SUM(C22:H22) -> 3470
B23: Var % vs plan | C23: =IF(C22="","",C22/C21-1) -> 0.0046224961 | D23: =IF(D22="","",D22/D21-1) -> 0.022462562 | E23: =IF(E22="","",E22/E21-1) -> -0.30022405 | F23: =IF(F22="","",F22/F21-1) | G23: =IF(G22="","",G22/G21-1) | H23: =IF(H22="","",H22/H21-1) | I23: =IF(SUM(C22:E22)=0,"",SUM(C22:E22)/SUM(C21:E21)-1) -> -0.096118781
B24: BOP | C24: 2164 | D24: =C25 -> 1923 | E24: =D25 -> 2142 | F24: =E25 -> 2070 | G24: =F25 -> 3030 | H24: =G25 -> 2178 | I24: =C24 -> 2164
B25: Planned EOP | C25: 1923 | D25: 2142 | E25: 2070 | F25: 3030 | G25: 2178 | H25: 1525 | I25: =H25 -> 1525
B26: Planned Receipts | C26: =C21+C25-C24 -> 1057 | D26: =D21+D25-D24 -> 1421 | E26: =E21+E25-E24 -> 1267 | F26: =F21+F25-F24 -> 2254 | G26: =G21+G25-G24 -> 1042 | H26: =H21+H25-H24 -> 708 | I26: =SUM(C26:H26) -> 7749
B27: On Order | C27: 1092 | D27: 1432 | E27: 1136 | F27: 1630 | G27: 450 | H27: 146 | I27: =SUM(C27:H27) -> 5886
B28: OTB | C28: =C26-C27 -> -35 | D28: =D26-D27 -> -11 | E28: =E26-E27 -> 131 | F28: =F26-F27 -> 624 | G28: =G26-G27 -> 592 | H28: =H26-H27 -> 562 | I28: =SUM(C28:H28) -> 1863
A29: Footwear | B29: Planned Sales | C29: 607 | D29: 846 | E29: 991 | F29: 1194 | G29: 1671 | H29: 1127 | I29: =SUM(C29:H29) -> 6436
B30: Actual Sales | C30: 539 | D30: 690 | E30: 697 | I30: =SUM(C30:H30) -> 1926
B31: Var % vs plan | C31: =IF(C30="","",C30/C29-1) -> -0.11202636 | D31: =IF(D30="","",D30/D29-1) -> -0.18439716 | E31: =IF(E30="","",E30/E29-1) -> -0.29667003 | F31: =IF(F30="","",F30/F29-1) | G31: =IF(G30="","",G30/G29-1) | H31: =IF(H30="","",H30/H29-1) | I31: =IF(SUM(C30:E30)=0,"",SUM(C30:E30)/SUM(C29:E29)-1) -> -0.21194763
B32: BOP | C32: 1170 | D32: =C33 -> 1861 | E32: =D33 -> 2180 | F32: =E33 -> 2627 | G32: =F33 -> 3676 | H32: =G33 -> 2479 | I32: =C32 -> 1170
B33: Planned EOP | C33: 1861 | D33: 2180 | E33: 2627 | F33: 3676 | G33: 2479 | H33: 1736 | I33: =H33 -> 1736
B34: Planned Receipts | C34: =C29+C33-C32 -> 1298 | D34: =D29+D33-D32 -> 1165 | E34: =E29+E33-E32 -> 1438 | F34: =F29+F33-F32 -> 2243 | G34: =G29+G33-G32 -> 474 | H34: =H29+H33-H32 -> 384 | I34: =SUM(C34:H34) -> 7002
B35: On Order | C35: 1341 | D35: 1219 | E35: 1337 | F35: 1630 | G35: 221 | H35: 80 | I35: =SUM(C35:H35) -> 5828
B36: OTB | C36: =C34-C35 -> -43 | D36: =D34-D35 -> -54 | E36: =E34-E35 -> 101 | F36: =F34-F35 -> 613 | G36: =G34-G35 -> 253 | H36: =H34-H35 -> 304 | I36: =SUM(C36:H36) -> 1174
A37: Accessories | B37: Planned Sales | C37: 710 | D37: 799 | E37: 1041 | F37: 1314 | G37: 1774 | H37: 1200 | I37: =SUM(C37:H37) -> 6838
B38: Actual Sales | C38: 632 | D38: 752 | E38: 833 | I38: =SUM(C38:H38) -> 2217
B39: Var % vs plan | C39: =IF(C38="","",C38/C37-1) -> -0.10985915 | D39: =IF(D38="","",D38/D37-1) -> -0.058823529 | E39: =IF(E38="","",E38/E37-1) -> -0.19980788 | F39: =IF(F38="","",F38/F37-1) | G39: =IF(G38="","",G38/G37-1) | H39: =IF(H38="","",H38/H37-1) | I39: =IF(SUM(C38:E38)=0,"",SUM(C38:E38)/SUM(C37:E37)-1) -> -0.13058824
B40: BOP | C40: 1244 | D40: =C41 -> 1438 | E40: =D41 -> 1874 | F40: =E41 -> 2365 | G40: =F41 -> 3193 | H40: =G41 -> 2160 | I40: =C40 -> 1244
...

Sheet OTB_v3_luglio
A1: VERSIONE LUGLIO - NON USARE (valori incollati)
A2: Regione | B2: Categoria | C2: Ago-26 | D2: Set-26 | E2: Ott-26 | F2: Nov-26 | G2: Dic-26 | H2: Gen-27
A3: EMEA | B3: Outerwear | C3: 5386 | D3: 9640 | E3: 14576 | F3: 20389 | G3: 33462 | H3: 23239
A4: EMEA | B4: Knitwear | C4: 1454 | D4: 1561 | E4: 1681 | F4: 2417 | G4: 3586 | H4: 2155
A5: EMEA | B5: Jersey | C5: 1249 | D5: 1246 | E5: 1108 | F5: 1212 | G5: 1866 | H5: 1475
A6: EMEA | B6: Footwear | C6: 520 | D6: 721 | E6: 961 | F6: 1295 | G6: 1936 | H6: 1337
A7: EMEA | B7: Accessories | C7: 670 | D7: 879 | E7: 1000 | F7: 1333 | G7: 2464 | H7: 1439
A8: EMEA | B8: Bottoms | C8: 76 | D8: 90 | E8: 149 | F8: 220 | G8: 594 | H8: 323
A9: AMERICAS | B9: Outerwear | C9: 1656 | D9: 2389 | E9: 4053 | F9: 6376 | G9: 9690 | H9: 6458
A10: AMERICAS | B10: Knitwear | C10: 281 | D10: 408 | E10: 458 | F10: 476 | G10: 871 | H10: 567
A11: AMERICAS | B11: Jersey | C11: 387 | D11: 374 | E11: 399 | F11: 449 | G11: 513 | H11: 445
A12: AMERICAS | B12: Footwear | C12: 138 | D12: 173 | E12: 246 | F12: 290 | G12: 560 | H12: 344
A13: AMERICAS | B13: Accessories | C13: 167 | D13: 235 | E13: 250 | F13: 358 | G13: 676 | H13: 369
A14: AMERICAS | B14: Bottoms | C14: 13 | D14: 15 | E14: 36 | F14: 63 | G14: 147 | H14: 64
... A20: APAC | B20: Bottoms | C20: 26 | D20: 39 | E20: 93 | F20: 97 | G20: 133 | H20: 93
